Workbook

Sheet Report.csv
A1: Genome | B1: Genome Name/ Sample Name | C1: Region_ID | D1: Scaffold | E1: Cluster_Type | F1: Predicted_Product | G1: Region_Start | H1: Region_End | I1: Region_Length | J1: ORF_Count | K1: Core_Gene_Count | L1: Tailoring_Gene_Count | M1: Transport_Gene_Count | N1: Regulatory_Gene_Count | O1: Strand_Orientation | P1: GC_Content | Q1: ORF_Density | R1: MiBIG_Hits
A2: 8132433368 | B2: {=INDEX(Sheet2!B:B, MATCH(A2, Sheet2!A:A, 0))} -> Rothia mucilaginosa 110740021-2 | C2: Ga0680089_01.region001 | D2: Ga0680089_01 | E2: Unknown | F2: NRPS | G2: 1015 | H2: 43294 | I2: 42280 | J2: 37 | K2: 0 | L2: 0 | M2: 0 | N2: 0 | O2: + | P2: 59.97 | Q2: 0.0009
A3: 8132450495 | B3: {=INDEX(Sheet2!B:B, MATCH(A3, Sheet2!A:A, 0))} -> Kocuria rhizophila 111540051-3 | C3: Ga0680103_01.region003 | D3: Ga0680103_01 | E3: Unknown | F3: NAPAA | G3: 1571 | H3: 33678 | I3: 32108 | J3: 30 | K3: 0 | L3: 0 | M3: 0 | N3: 0 | O3: + | P3: 73.41 | Q3: 0.0009
A4: 8132450495 | B4: {=INDEX(Sheet2!B:B, MATCH(A4, Sheet2!A:A, 0))} -> Kocuria rhizophila 111540051-3 | C4: Ga0680103_01.region001 | D4: Ga0680103_01 | E4: Unknown | F4: T3PKS | G4: 622 | H4: 40918 | I4: 40297 | J4: 42 | K4: 0 | L4: 0 | M4: 0 | N4: 0 | O4: + | P4: 71.02 | Q4: 0.001
A5: 8132450495 | B5: {=INDEX(Sheet2!B:B, MATCH(A5, Sheet2!A:A, 0))} -> Kocuria rhizophila 111540051-3 | C5: Ga0680103_01.region002 | D5: Ga0680103_01 | E5: Unknown | F5: NI-siderophore | G5: 843 | H5: 29297 | I5: 28455 | J5: 25 | K5: 0 | L5: 0 | M5: 0 | N5: 0 | O5: + | P5: 71.76 | Q5: 0.0009
A6: 8132450495 | B6: {=INDEX(Sheet2!B:B, MATCH(A6, Sheet2!A:A, 0))} -> Kocuria rhizophila 111540051-3 | C6: Ga0680103_03.region001 | D6: Ga0680103_03 | E6: Unknown | F6: betalactone | G6: 362 | H6: 25473 | I6: 25112 | J6: 23 | K6: 0 | L6: 0 | M6: 0 | N6: 0 | O6: - | P6: 72.65 | Q6: 0.0009
A7: 8132450495 | B7: {=INDEX(Sheet2!B:B, MATCH(A7, Sheet2!A:A, 0))} -> Kocuria rhizophila 111540051-3 | C7: Ga0680103_09.region001 | D7: Ga0680103_09 | E7: Unknown | F7: terpene | G7: 313 | H7: 20436 | I7: 20124 | J7: 20 | K7: 0 | L7: 0 | M7: 0 | N7: 0 | O7: + | P7: 72.27 | Q7: 0.001
A8: 8132503709 | B8: {=INDEX(Sheet2!B:B, MATCH(A8, Sheet2!A:A, 0))} -> Staphylococcus warneri 121210007-3 | C8: Ga0680131_12.region001 | D8: Ga0680131_12 | E8: Unknown | F8: NI-siderophore | G8: 258 | H8: 32141 | I8: 31884 | J8: 32 | K8: 0 | L8: 0 | M8: 0 | N8: 0 | O8: + | P8: 32.02 | Q8: 0.001
A9: 8132503709 | B9: {=INDEX(Sheet2!B:B, MATCH(A9, Sheet2!A:A, 0))} -> Staphylococcus warneri 121210007-3 | C9: Ga0680131_03.region001 | D9: Ga0680131_03 | E9: Unknown | F9: T3PKS | G9: 70 | H9: 46782 | I9: 46713 | J9: 50 | K9: 0 | L9: 0 | M9: 0 | N9: 0 | O9: + | P9: 33.56 | Q9: 0.0011
A10: 8132503709 | B10: {=INDEX(Sheet2!B:B, MATCH(A10, Sheet2!A:A, 0))} -> Staphylococcus warneri 121210007-3 | C10: Ga0680131_05.region001 | D10: Ga0680131_05 | E10: Unknown | F10: cyclic-lactone-autoinducer | G10: 602 | H10: 19143 | I10: 18542 | J10: 21 | K10: 0 | L10: 0 | M10: 0 | N10: 0 | O10: - | P10: 31.71 | Q10: 0.0011
A11: 8132551458 | B11: {=INDEX(Sheet2!B:B, MATCH(A11, Sheet2!A:A, 0))} -> Ralstonia insidiosa 121560039-2 | C11: Ga0680158_01.region001 | D11: Ga0680158_01 | E11: Unknown | F11: terpene | G11: 1536 | H11: 20075 | I11: 18540 | J11: 14 | K11: 0 | L11: 0 | M11: 0 | N11: 0 | O11: + | P11: 63.42 | Q11: 0.0008
A12: 8132551458 | B12: {=INDEX(Sheet2!B:B, MATCH(A12, Sheet2!A:A, 0))} -> Ralstonia insidiosa 121560039-2 | C12: Ga0680158_09.region001 | D12: Ga0680158_09 | E12: Unknown | F12: butyrolactone | G12: 685 | H12: 8770 | I12: 8086 | J12: 9 | K12: 0 | L12: 0 | M12: 0 | N12: 0 | O12: + | P12: 63.24 | Q12: 0.0011
A13: 8132551458 | B13: {=INDEX(Sheet2!B:B, MATCH(A13, Sheet2!A:A, 0))} -> Ralstonia insidiosa 121560039-2 | C13: Ga0680158_04.region001 | D13: Ga0680158_04 | E13: Unknown | F13: T1PKS | G13: 746 | H13: 47139 | I13: 46394 | J13: 56 | K13: 0 | L13: 0 | M13: 0 | N13: 0 | O13: + | P13: 61.27 | Q13: 0.0012
... A95: 8135715517 | B95: {=INDEX(Sheet2!B:B, MATCH(A95, Sheet2!A:A, 0))} -> Kocuria marina F10_7S_D2_EB4 | C95: Ga0685613_07.region001 | D95: Ga0685613_07 | E95: Unknown | F95: terpene | G95: 699 | H95: 20212 | I95: 19514 | J95: 21 | K95: 0 | L95: 0 | M95: 0 | N95: 0 | O95: - | P95: 69.51 | Q95: 0.0011

Sheet Antismash_html
A1: Assembly | B1: Genome Name/ Sample Name | C1: Strain_id | D1: Title | E1: Region | F1: Type | G1: From | H1: To | I1: Most_similar_known_cluster | J1: Cluster_category | K1: Similarity
A2: 8132450495 | B2: {=INDEX(Sheet2!B:B, MATCH(A2, Sheet2!A:A, 0))} -> Kocuria rhizophila 111540051-3 | D2: Ga0680103_01 | E2: Region 1.1 | F2: T3PKS | G2: 503866 | H2: 545071 | I2: avilamycin A/avilamycin C | J2: Saccharide:Oligosaccharide | K2: 0.05
A3: 8132450495 | B3: {=INDEX(Sheet2!B:B, MATCH(A3, Sheet2!A:A, 0))} -> Kocuria rhizophila 111540051-3 | D3: Ga0680103_01 | E3: Region 1.2 | F3: NI-siderophore | G3: 917205 | H3: 947136
A4: 8132450495 | B4: {=INDEX(Sheet2!B:B, MATCH(A4, Sheet2!A:A, 0))} -> Kocuria rhizophila 111540051-3 | D4: Ga0680103_01 | E4: Region 1.3 | F4: NAPAA | G4: 973515 | H4: 1007663
A5: 8132450495 | B5: {=INDEX(Sheet2!B:B, MATCH(A5, Sheet2!A:A, 0))} -> Kocuria rhizophila 111540051-3 | D5: Ga0680103_03 | E5: Region 3.1 | F5: betalactone | G5: 33178 | H5: 60033 | I5: microansamycin | J5: Polyketide | K5: 0.07
A6: 8132450495 | B6: {=INDEX(Sheet2!B:B, MATCH(A6, Sheet2!A:A, 0))} -> Kocuria rhizophila 111540051-3 | D6: Ga0680103_09 | E6: Region 9.1 | F6: terpene | G6: 1121 | H6: 22020 | I6: carotenoid | J6: Terpene | K6: 0.33
A7: 8133623617 | B7: {=INDEX(Sheet2!B:B, MATCH(A7, Sheet2!A:A, 0))} -> Ralstonia insidiosa 151470044-1 | D7: Ga0680996_02 | E7: Region 2.1 | F7: terpene | G7: 437108 | H7: 457941
A8: 8133623617 | B8: {=INDEX(Sheet2!B:B, MATCH(A8, Sheet2!A:A, 0))} -> Ralstonia insidiosa 151470044-1 | D8: Ga0680996_02 | E8: Region 2.2 | F8: NI-siderophore | G8: 460286 | H8: 490172 | I8: alcaligin | J8: Other | K8: 0.62
A9: 8133623617 | B9: {=INDEX(Sheet2!B:B, MATCH(A9, Sheet2!A:A, 0))} -> Ralstonia insidiosa 151470044-1 | D9: Ga0680996_03 | E9: Region 3.1 | F9: T1PKS | G9: 567397 | H9: 615025 | I9: lipopolysaccharide | J9: Saccharide:Lipopolysaccharide | K9: 0.05
A10: 8133623617 | B10: {=INDEX(Sheet2!B:B, MATCH(A10, Sheet2!A:A, 0))} -> Ralstonia insidiosa 151470044-1 | D10: Ga0680996_04 | E10: Region 4.1 | F10: arylpolyene | G10: 256944 | H10: 298176
A11: 8133623617 | B11: {=INDEX(Sheet2!B:B, MATCH(A11, Sheet2!A:A, 0))} -> Ralstonia insidiosa 151470044-1 | D11: Ga0680996_07 | E11: Region 7.1 | F11: redox-cofactor | G11: 136524 | H11: 158643 | I11: lankacidin C | J11: NRP+Polyketide | K11: 0.13
A12: 8133623617 | B12: {=INDEX(Sheet2!B:B, MATCH(A12, Sheet2!A:A, 0))} -> Ralstonia insidiosa 151470044-1 | D12: Ga0680996_08 | E12: Region 8.1 | F12: butyrolactone | G12: 5985 | H12: 16692
A13: 8133623617 | B13: {=INDEX(Sheet2!B:B, MATCH(A13, Sheet2!A:A, 0))} -> Ralstonia insidiosa 151470044-1 | D13: Ga0680996_14 | E13: Region 14.1 | F13: betalactone | G13: 71158 | H13: 96157 | I13: corynecin III/corynecin I/corynecin II | J13: Other | K13: 0.13
A14: 8133623617 | B14: {=INDEX(Sheet2!B:B, MATCH(A14, Sheet2!A:A, 0))} -> Ralstonia insidiosa 151470044-1 | D14: Ga0680996_20 | E14: Region 20.1 | F14: hydrogen-cyanide | G14: 28964 | H14: 41849
A15: 8132601599 | B15: {=INDEX(Sheet2!B:B, MATCH(A15, Sheet2!A:A, 0))} -> Ralstonia insidiosa 130770013-1 | D15: Ga0680183_01 | E15: Region 1.1 | F15: NI-siderophore | G15: 462140 | H15: 492026 | I15: alcaligin | J15: Other | K15: 0.62
A16: 8132601599 | B16: {=INDEX(Sheet2!B:B, MATCH(A16, Sheet2!A:A, 0))} -> Ralstonia insidiosa 130770013-1 | D16: Ga0680183_01 | E16: Region 1.2 | F16: terpene | G16: 494371 | H16: 515204
A17: 8132601599 | B17: {=INDEX(Sheet2!B:B, MATCH(A17, Sheet2!A:A, 0))} -> Ralstonia insidiosa 130770013-1 | D17: Ga0680183_03 | E17: Region 3.1 | F17: T1PKS | G17: 32507 | H17: 80135 | I17: lipopolysaccharide | J17: Saccharide:Lipopolysaccharide | K17: 0.05
A18: 8132601599 | B18: {=INDEX(Sheet2!B:B, MATCH(A18, Sheet2!A:A, 0))} -> Ralstonia insidiosa 130770013-1 | D18: Ga0680183_04 | E18: Region 4.1 | F18: arylpolyene | G18: 70292 | H18: 111524
A19: 8132601599 | B19: {=INDEX(Sheet2!B:B, MATCH(A19, Sheet2!A:A, 0))} -> Ralstonia insidiosa 130770013-1 | D19: Ga0680183_07 | E19: Region 7.1 | F19: redox-cofactor | G19: 136524 | H19: 158643 | I19: lankacidin C | J19: NRP+Polyketide | K19: 0.13
A20: 8132601599 | B20: {=INDEX(Sheet2!B:B, MATCH(A20, Sheet2!A:A, 0))} -> Ralstonia insidiosa 130770013-1 | D20: Ga0680183_08 | E20: Region 8.1 | F20: butyrolactone | G20: 285991 | H20: 296698
A21: 8132601599 | B21: {=INDEX(Sheet2!B:B, MATCH(A21, Sheet2!A:A, 0))} -> Ralstonia insidiosa 130770013-1 | D21: Ga0680183_13 | E21: Region 13.1 | F21: betalactone | G21: 82971 | H21: 107970 | I21: corynecin III/corynecin I/corynecin II | J21: Other | K21: 0.13
A22: 8132601599 | B22: {=INDEX(Sheet2!B:B, MATCH(A22, Sheet2!A:A, 0))} -> Ralstonia insidiosa 130770013-1 | D22: Ga0680183_19 | E22: Region 19.1 | F22: hydrogen-cyanide | G22: 58069 | H22: 70954
A23: 8132503709 | B23: {=INDEX(Sheet2!B:B, MATCH(A23, Sheet2!A:A, 0))} -> Staphylococcus warneri 121210007-3 | D23: Ga0680131_03 | E23: Region 3.1 | F23: terpene,T3PKS | G23: 16709 | H23: 63733
A24: 8132503709 | B24: {=INDEX(Sheet2!B:B, MATCH(A24, Sheet2!A:A, 0))} -> Staphylococcus warneri 121210007-3 | D24: Ga0680131_05 | E24: Region 5.1 | F24: cyclic-lactone-autoinducer | G24: 139864 | H24: 160599 | I24: N-tetradecanoyl tyrosine | J24: Other | K24: 0.06
A25: 8132503709 | B25: {=INDEX(Sheet2!B:B, MATCH(A25, Sheet2!A:A, 0))} -> Staphylococcus warneri 121210007-3 | D25: Ga0680131_12 | E25: Region 12.1 | F25: NI-siderophore | G25: 23592 | H25: 56579 | I25: staphyloferrin A | J25: Other:Non-NRP siderophore | K25: 1
A26: 8133476785 | B26: {=INDEX(Sheet2!B:B, MATCH(A26, Sheet2!A:A, 0))} -> Sphingomonas lutea F9_3S_D5_B_2 | D26: Ga0680769_01 | E26: Region 1.1 | F26: T3PKS | G26: 169063 | H26: 210109 | I26: stenothricin | J26: NRP:Cyclic depsipeptide | K26: 0.09
A27: 8133341747 | B27: {=INDEX(Sheet2!B:B, MATCH(A27, Sheet2!A:A, 0))} -> Streptococcus sp. 151470009-6 | D27: Ga0680995_04 | E27: Region 4.1 | F27: T3PKS | G27: 105246 | H27: 146418
A28: 8133992572 | B28: {=INDEX(Sheet2!B:B, MATCH(A28, Sheet2!A:A, 0))} -> Staphylococcus hominis 153480033-6 | D28: Ga0681033_04 | E28: Region 4.1 | F28: NI-siderophore | G28: 52244 | H28: 82893 | I28: staphyloferrin A | J28: Other:Non-NRP siderophore | K28: 0.75
A29: 8133992572 | B29: {=INDEX(Sheet2!B:B, MATCH(A29, Sheet2!A:A, 0))} -> Staphylococcus hominis 153480033-6 | D29: Ga0681033_09 | E29: Region 9.1 | F29: terpene,T3PKS | G29: 15797 | H29: 63548
A30: 8133992572 | B30: {=INDEX(Sheet2!B:B, MATCH(A30, Sheet2!A:A, 0))} -> Staphylococcus hominis 153480033-6 | D30: Ga0681033_32 | E30: Region 32.1 | F30: cyclic-lactone-autoinducer | G30: 15631 | H30: 27114
A31: 8132824355 | B31: {=INDEX(Sheet2!B:B, MATCH(A31, Sheet2!A:A, 0))} -> Ralstonia insidiosa 142550021-1 | D31: Ga0680262_02 | E31: Region 2.1 | F31: terpene | G31: 437108 | H31: 457941
A32: 8132824355 | B32: {=INDEX(Sheet2!B:B, MATCH(A32, Sheet2!A:A, 0))} -> Ralstonia insidiosa 142550021-1 | D32: Ga0680262_02 | E32: Region 2.2 | F32: NI-siderophore | G32: 460286 | H32: 490172 | I32: alcaligin | J32: Other | K32: 0.62
A33: 8132824355 | B33: {=INDEX(Sheet2!B:B, MATCH(A33, Sheet2!A:A, 0))} -> Ralstonia insidiosa 142550021-1 | D33: Ga0680262_03 | E33: Region 3.1 | F33: T1PKS | G33: 32507 | H33: 80135 | I33: lipopolysaccharide | J33: Saccharide:Lipopolysaccharide | K33: 0.05
A34: 8132824355 | B34: {=INDEX(Sheet2!B:B, MATCH(A34, Sheet2!A:A, 0))} -> Ralstonia insidiosa 142550021-1 | D34: Ga0680262_04 | E34: Region 4.1 | F34: arylpolyene | G34: 256944 | H34: 298176
A35: 8132824355 | B35: {=INDEX(Sheet2!B:B, MATCH(A35, Sheet2!A:A, 0))} -> Ralstonia insidiosa 142550021-1 | D35: Ga0680262_07 | E35: Region 7.1 | F35: redox-cofactor | G35: 152062 | H35: 174181 | I35: lankacidin C | J35: NRP+Polyketide | K35: 0.13
A36: 8132824355 | B36: {=INDEX(Sheet2!B:B, MATCH(A36, Sheet2!A:A, 0))} -> Ralstonia insidiosa 142550021-1 | D36: Ga0680262_08 | E36: Region 8.1 | F36: butyrolactone | G36: 5985 | H36: 16692
A37: 8132824355 | B37: {=INDEX(Sheet2!B:B, MATCH(A37, Sheet2!A:A, 0))} -> Ralstonia insidiosa 142550021-1 | D37: Ga0680262_14 | E37: Region 14.1 | F37: betalactone | G37: 82971 | H37: 107970 | I37: corynecin III/corynecin I/corynecin II | J37: Other | K37: 0.13
A38: 8132824355 | B38: {=INDEX(Sheet2!B:B, MATCH(A38, Sheet2!A:A, 0))} -> Ralstonia insidiosa 142550021-1 | D38: Ga0680262_20 | E38: Region 20.1 | F38: hydrogen-cyanide | G38: 58069 | H38: 70954
A39: 8132433368 | B39: {=INDEX(Sheet2!B:B, MATCH(A39, Sheet2!A:A, 0))} -> Rothia mucilaginosa 110740021-2 | D39: Ga0680089_01 | E39: Region 1.1 | F39: NRPS | G39: 800807 | H39: 845174 | I39: enterobactin | J39: NRP | K39: 0.88
A40: 8132818425 | B40: {=INDEX(Sheet2!B:B, MATCH(A40, Sheet2!A:A, 0))} -> Ralstonia insidiosa 142550027-2 | D40: Ga0680261_01 | E40: Region 1.1 | F40: terpene | G40: 437108 | H40: 457941
...

Sheet <50%
A1: Assembly | B1: Genome Name/ Sample Name | C1: Similarity | D1: Folder_Name | E1: Region | F1: Type | G1: From | H1: To | I1: Most_similar_known_cluster | J1: Cluster_category
A2: 8132450495 | B2: {=INDEX(Sheet2!B:B, MATCH(A2, Sheet2!A:A, 0))} -> Kocuria rhizophila 111540051-3 | C2: Ga0680103_01 | D2: Region 1.1 | E2: T3PKS | F2: 503866 | G2: 545071 | H2: avilamycin A/avilamycin C | I2: Saccharide:Oligosaccharide | J2: 0.05
A3: 8132450495 | B3: {=INDEX(Sheet2!B:B, MATCH(A3, Sheet2!A:A, 0))} -> Kocuria rhizophila 111540051-3 | C3: Ga0680103_03 | D3: Region 3.1 | E3: betalactone | F3: 33178 | G3: 60033 | H3: microansamycin | I3: Polyketide | J3: 0.07
A4: 8132450495 | B4: {=INDEX(Sheet2!B:B, MATCH(A4, Sheet2!A:A, 0))} -> Kocuria rhizophila 111540051-3 | C4: Ga0680103_09 | D4: Region 9.1 | E4: terpene | F4: 1121 | G4: 22020 | H4: carotenoid | I4: Terpene | J4: 0.33
A5: 8133623617 | B5: {=INDEX(Sheet2!B:B, MATCH(A5, Sheet2!A:A, 0))} -> Ralstonia insidiosa 151470044-1 | C5: Ga0680996_03 | D5: Region 3.1 | E5: T1PKS | F5: 567397 | G5: 615025 | H5: lipopolysaccharide | I5: Saccharide:Lipopolysaccharide | J5: 0.05
A6: 8133623617 | B6: {=INDEX(Sheet2!B:B, MATCH(A6, Sheet2!A:A, 0))} -> Ralstonia insidiosa 151470044-1 | C6: Ga0680996_07 | D6: Region 7.1 | E6: redox-cofactor | F6: 136524 | G6: 158643 | H6: lankacidin C | I6: NRP+Polyketide | J6: 0.13
A7: 8133623617 | B7: {=INDEX(Sheet2!B:B, MATCH(A7, Sheet2!A:A, 0))} -> Ralstonia insidiosa 151470044-1 | C7: Ga0680996_14 | D7: Region 14.1 | E7: betalactone | F7: 71158 | G7: 96157 | H7: corynecin III/corynecin I/corynecin II | I7: Other | J7: 0.13
A8: 8132601599 | B8: {=INDEX(Sheet2!B:B, MATCH(A8, Sheet2!A:A, 0))} -> Ralstonia insidiosa 130770013-1 | C8: Ga0680183_03 | D8: Region 3.1 | E8: T1PKS | F8: 32507 | G8: 80135 | H8: lipopolysaccharide | I8: Saccharide:Lipopolysaccharide | J8: 0.05
A9: 8132601599 | B9: {=INDEX(Sheet2!B:B, MATCH(A9, Sheet2!A:A, 0))} -> Ralstonia insidiosa 130770013-1 | C9: Ga0680183_07 | D9: Region 7.1 | E9: redox-cofactor | F9: 136524 | G9: 158643 | H9: lankacidin C | I9: NRP+Polyketide | J9: 0.13
A10: 8132601599 | B10: {=INDEX(Sheet2!B:B, MATCH(A10, Sheet2!A:A, 0))} -> Ralstonia insidiosa 130770013-1 | C10: Ga0680183_13 | D10: Region 13.1 | E10: betalactone | F10: 82971 | G10: 107970 | H10: corynecin III/corynecin I/corynecin II | I10: Other | J10: 0.13
A11: 8132503709 | B11: {=INDEX(Sheet2!B:B, MATCH(A11, Sheet2!A:A, 0))} -> Staphylococcus warneri 121210007-3 | C11: Ga0680131_05 | D11: Region 5.1 | E11: cyclic-lactone-autoinducer | F11: 139864 | G11: 160599 | H11: N-tetradecanoyl tyrosine | I11: Other | J11: 0.06
A12: 8133476785 | B12: {=INDEX(Sheet2!B:B, MATCH(A12, Sheet2!A:A, 0))} -> Sphingomonas lutea F9_3S_D5_B_2 | C12: Ga0680769_01 | D12: Region 1.1 | E12: T3PKS | F12: 169063 | G12: 210109 | H12: stenothricin | I12: NRP:Cyclic depsipeptide | J12: 0.09
A13: 8132824355 | B13: {=INDEX(Sheet2!B:B, MATCH(A13, Sheet2!A:A, 0))} -> Ralstonia insidiosa 142550021-1 | C13: Ga0680262_03 | D13: Region 3.1 | E13: T1PKS | F13: 32507 | G13: 80135 | H13: lipopolysaccharide | I13: Saccharide:Lipopolysaccharide | J13: 0.05
... A35: 8134898396 | B35: {=INDEX(Sheet2!B:B, MATCH(A35, Sheet2!A:A, 0))} -> Staphylococcus warneri 140720001-1 | C35: Ga0680230_07 | D35: Region 7.1 | E35: cyclic-lactone-autoinducer | F35: 16637 | G35: 37372 | H35: N-tetradecanoyl tyrosine | I35: Other | J35: 0.06

Sheet 50% - 70%
A1: Assembly | B1: Genome Name/ Sample Name | C1: Similarity | D1: Folder_Name | E1: Region | F1: Type | G1: From | H1: To | I1: Most_similar_known_cluster | J1: Cluster_category
A2: 8133623617 | B2: {=INDEX(Sheet2!B:B, MATCH(A2, Sheet2!A:A, 0))} -> Ralstonia insidiosa 151470044-1 | C2: Ga0680996_02 | D2: Region 2.2 | E2: NI-siderophore | F2: 460286 | G2: 490172 | H2: alcaligin | I2: Other | J2: 0.62
A3: 8132601599 | B3: {=INDEX(Sheet2!B:B, MATCH(A3, Sheet2!A:A, 0))} -> Ralstonia insidiosa 130770013-1 | C3: Ga0680183_01 | D3: Region 1.1 | E3: NI-siderophore | F3: 462140 | G3: 492026 | H3: alcaligin | I3: Other | J3: 0.62
A4: 8132824355 | B4: {=INDEX(Sheet2!B:B, MATCH(A4, Sheet2!A:A, 0))} -> Ralstonia insidiosa 142550021-1 | C4: Ga0680262_02 | D4: Region 2.2 | E4: NI-siderophore | F4: 460286 | G4: 490172 | H4: alcaligin | I4: Other | J4: 0.62
A5: 8132818425 | B5: {=INDEX(Sheet2!B:B, MATCH(A5, Sheet2!A:A, 0))} -> Ralstonia insidiosa 142550027-2 | C5: Ga0680261_01 | D5: Region 1.2 | E5: NI-siderophore | F5: 460286 | G5: 490172 | H5: alcaligin | I5: Other | J5: 0.62
A6: 8133635480 | B6: {=INDEX(Sheet2!B:B, MATCH(A6, Sheet2!A:A, 0))} -> Ralstonia insidiosa 151470066-2 | C6: Ga0680998_02 | D6: Region 2.2 | E6: NI-siderophore | F6: 460286 | G6: 490172 | H6: alcaligin | I6: Other | J6: 0.62
A7: 8133629549 | B7: {=INDEX(Sheet2!B:B, MATCH(A7, Sheet2!A:A, 0))} -> Ralstonia insidiosa 151470066-1 | C7: Ga0680997_02 | D7: Region 2.2 | E7: NI-siderophore | F7: 460286 | G7: 490172 | H7: alcaligin | I7: Other | J7: 0.62
A8: 8132595571 | B8: {=INDEX(Sheet2!B:B, MATCH(A8, Sheet2!A:A, 0))} -> Ralstonia insidiosa 123250053-1 | C8: Ga0680181_02 | D8: Region 2.2 | E8: NI-siderophore | F8: 460286 | G8: 490172 | H8: alcaligin | I8: Other | J8: 0.62
A9: 8132551458 | B9: {=INDEX(Sheet2!B:B, MATCH(A9, Sheet2!A:A, 0))} -> Ralstonia insidiosa 121560039-2 | C9: Ga0680158_01 | D9: Region 1.2 | E9: NI-siderophore | F9: 460285 | G9: 490171 | H9: alcaligin | I9: Other | J9: 0.62

Sheet 70% -90%
A1: Assembly | B1: Genome Name/ Sample Name | C1: Similarity | D1: Folder_Name | E1: Region | F1: Type | G1: From | H1: To | I1: Most_similar_known_cluster | J1: Cluster_category
A2: 8133992572 | B2: {=INDEX(Sheet2!B:B, MATCH(A2, Sheet2!A:A, 0))} -> Staphylococcus hominis 153480033-6 | C2: Ga0681033_04 | D2: Region 4.1 | E2: NI-siderophore | F2: 52244 | G2: 82893 | H2: staphyloferrin A | I2: Other:Non-NRP siderophore | J2: 0.75
A3: 8132433368 | B3: {=INDEX(Sheet2!B:B, MATCH(A3, Sheet2!A:A, 0))} -> Rothia mucilaginosa 110740021-2 | C3: Ga0680089_01 | D3: Region 1.1 | E3: NRPS | F3: 800807 | G3: 845174 | H3: enterobactin | I3: NRP | J3: 0.88

Sheet >90%
A1: Assembly | B1: Genome Name/ Sample Name | C1: Similarity | D1: Folder_Name | E1: Region | F1: Type | G1: From | H1: To | I1: Most_similar_known_cluster | J1: Cluster_category
A2: 8132503709 | B2: {=INDEX(Sheet2!B:B, MATCH(A2, Sheet2!A:A, 0))} -> Staphylococcus warneri 121210007-3 | C2: Ga0680131_12 | D2: Region 12.1 | E2: NI-siderophore | F2: 23592 | G2: 56579 | H2: staphyloferrin A | I2: Other:Non-NRP siderophore | J2: 1
A3: 8133643943 | B3: {=INDEX(Sheet2!B:B, MATCH(A3, Sheet2!A:A, 0))} -> Methylorubrum extorquens 153480035-1 | C3: Ga0681003_15 | D3: Region 15.1 | E3: terpene | F3: 120026 | G3: 141087 | H3: carotenoid | I3: Terpene | J3: 1
A4: 8134898396 | B4: {=INDEX(Sheet2!B:B, MATCH(A4, Sheet2!A:A, 0))} -> Staphylococcus warneri 140720001-1 | C4: Ga0680230_02 | D4: Region 2.1 | E4: NI-siderophore | F4: 810 | G4: 33797 | H4: staphyloferrin A | I4: Other:Non-NRP siderophore | J4: 1

Sheet Sheet2
A1: Assembly | B1: Strain Name / Genome Name
A2: 8133476785 | B2: Sphingomonas lutea F9_3S_D5_B_2
A3: 8133643943 | B3: Methylorubrum extorquens 153480035-1
A4: 8132450495 | B4: Kocuria rhizophila 111540051-3
A5: 8133992572 | B5: Staphylococcus hominis 153480033-6
A6: 8133341747 | B6: Streptococcus sp. 151470009-6
A7: 8132433368 | B7: Rothia mucilaginosa 110740021-2
A8: 8132551458 | B8: Ralstonia insidiosa 121560039-2
A9: 8133629549 | B9: Ralstonia insidiosa 151470066-1
A10: 8132824355 | B10: Ralstonia insidiosa 142550021-1
A11: 8133623617 | B11: Ralstonia insidiosa 151470044-1
A12: 8132818425 | B12: Ralstonia insidiosa 142550027-2
A13: 8132601599 | B13: Ralstonia insidiosa 130770013-1
... A18: 8135715517 | B18: Kocuria marina F10_7S_D2_EB4
